Workbook

Sheet KPI Data
A1: Task 1.2 - BRSR Essential Indicator Extraction: Wipro Limited FY 2024-25
A3: Sr No. | B3: KPI | C3: NGRBC Principle / Section | D3: Value | E3: Unit | F3: Financial Year | G3: Page
A4: 1 | B4: Revenue from operations (Turnover) | C4: Section VI - CSR Details | D4: 672928 | E4: INR Million | F4: FY 2024-25 | G4: 483
A5: 2 | B5: Total permanent employees | C5: Section IV, Q21a | D5: 225306 | E5: headcount | F5: FY 2024-25 | G5: 482
A6: 3 | B6: Female employees in permanent workforce | C6: Section IV, Q21a | D6: 0.3713 | E6: % of permanent | F6: FY 2024-25 | G6: 482
A7: 4 | B7: Employee turnover rate (permanent, total) | C7: Section IV, Q23 | D7: 0.1481 | E7: % (annual) | F7: FY 2024-25 | G7: 482
A8: 5 | B8: LTIFR | C8: Principle 3, Essential Q11 | D8: 0.27 | E8: per million person-hours | F8: FY 2024-25 | G8: 499
A9: 6 | B9: Scope 1 + Scope 2 GHG emissions | C9: Principle 6, Essential Q7 | D9: 31462 | E9: tCO2e | F9: FY 2024-25 | G9: 509
A10: 7 | B10: Water consumption (total) | C10: Principle 6, Essential Q3 | D10: 1307531 | E10: kilolitres | F10: FY 2024-25 | G10: 507
A11: 8 | B11: Total energy consumed | C11: Principle 6, Essential Q1 | D11: 7.5617553e+08 | E11: Megajoules | F11: FY 2024-25 | G11: 506
A12: 9 | B12: POSH complaints filed (Sexual Harassment) | C12: Principle 5, Essential Q7 | D12: 125 | E12: count (annual) | F12: FY 2024-25 | G12: 504

Sheet Completeness
A1: Task 1.3 - Completeness Score
A3: Scoring logic:
A4: A KPI counts as 'disclosed' (1) if the source BRSR reports a numeric value that answers the required indicator directly, on a stated page. It counts as 'not disclosed' (0) if the source is silent, or reports only a non-numeric 'Not Applicable' without an underlying value. This test - ISNUMBER on the KPI Data value cell - detects presence of a figure, not its correctness. It is a disclosure-completeness score, not a data-quality score, and every value it checks is a live cross-sheet reference to KPI Data, so the two sheets cannot drift out of sync.
A9: Sr No. | B9: KPI | C9: Value (linked) | D9: Disclosed (1/0) | E9: Page
A10: =1 -> 1 | B10: ='KPI Data'!B4 -> Revenue from operations (Turnover) | C10: ='KPI Data'!D4 -> 672928 | D10: =IF(ISNUMBER('KPI Data'!D4),1,0) -> 1 | E10: ='KPI Data'!G4 -> 483
A11: =2 -> 2 | B11: ='KPI Data'!B5 -> Total permanent employees | C11: ='KPI Data'!D5 -> 225306 | D11: =IF(ISNUMBER('KPI Data'!D5),1,0) -> 1 | E11: ='KPI Data'!G5 -> 482
A12: =3 -> 3 | B12: ='KPI Data'!B6 -> Female employees in permanent workforce | C12: ='KPI Data'!D6 -> 0.3713 | D12: =IF(ISNUMBER('KPI Data'!D6),1,0) -> 1 | E12: ='KPI Data'!G6 -> 482
A13: =4 -> 4 | B13: ='KPI Data'!B7 -> Employee turnover rate (permanent, total) | C13: ='KPI Data'!D7 -> 0.1481 | D13: =IF(ISNUMBER('KPI Data'!D7),1,0) -> 1 | E13: ='KPI Data'!G7 -> 482
A14: =5 -> 5 | B14: ='KPI Data'!B8 -> LTIFR | C14: ='KPI Data'!D8 -> 0.27 | D14: =IF(ISNUMBER('KPI Data'!D8),1,0) -> 1 | E14: ='KPI Data'!G8 -> 499
A15: =6 -> 6 | B15: ='KPI Data'!B9 -> Scope 1 + Scope 2 GHG emissions | C15: ='KPI Data'!D9 -> 31462 | D15: =IF(ISNUMBER('KPI Data'!D9),1,0) -> 1 | E15: ='KPI Data'!G9 -> 509
A16: =7 -> 7 | B16: ='KPI Data'!B10 -> Water consumption (total) | C16: ='KPI Data'!D10 -> 1307531 | D16: =IF(ISNUMBER('KPI Data'!D10),1,0) -> 1 | E16: ='KPI Data'!G10 -> 507
A17: =8 -> 8 | B17: ='KPI Data'!B11 -> Total energy consumed | C17: ='KPI Data'!D11 -> 7.5617553e+08 | D17: =IF(ISNUMBER('KPI Data'!D11),1,0) -> 1 | E17: ='KPI Data'!G11 -> 506
A18: =9 -> 9 | B18: ='KPI Data'!B12 -> POSH complaints filed (Sexual Harassment) | C18: ='KPI Data'!D12 -> 125 | D18: =IF(ISNUMBER('KPI Data'!D12),1,0) -> 1 | E18: ='KPI Data'!G12 -> 504
B19: KPIs disclosed: | D19: =SUM(D10:D18) -> 9
B20: Total target KPIs: | D20: =COUNTA(A10:A18) -> 9
B21: Completeness score: | D21: =D19/D20 -> 1

Sheet Intensity Ratios
A1: Task 1.4 - Intensity Ratios
A8: Part A - Computed Intensity Ratios
A9: Item | B9: Formula | C9: Value | D9: Unit
A10: Revenue (INR Crore) | B10: ='KPI Data'!D4 / 10 -> 67292.8 | C10: ='KPI Data'!D4 / 10 -> 67292.8 | D10: INR Crore
A11: Scope 1+2 GHG | B11: ='KPI Data'!D9 -> 31462 | C11: ='KPI Data'!D9 -> 31462 | D11: tCO2e
A12: Water consumption | B12: ='KPI Data'!D10 -> 1307531 | C12: ='KPI Data'!D10 -> 1307531 | D12: kilolitres (= m3)
A13: Total energy consumed | B13: ='KPI Data'!D11 -> 7.5617553e+08 | C13: ='KPI Data'!D11 -> 7.5617553e+08 | D13: Megajoules
A15: Ratio | B15: Formula | C15: Value | D15: Unit
A16: GHG intensity (Scope 1+2) | B16: =C11 / C10 -> 0.46753887 | C16: =C11 / C10 -> 0.46753887 | D16: tCO2e per INR Crore turnover
A17: Water intensity | B17: =C12 / C10 -> 19.430474 | C17: =C12 / C10 -> 19.430474 | D17: m3 (KL) per INR Crore turnover
A18: Energy intensity | B18: =C13 / C10 -> 11237.094 | C18: =C13 / C10 -> 11237.094 | D18: MJ per INR Crore turnover
A20: Part B - Reconciliation against Wipro's own printed intensities
A21: Wipro prints its own per-rupee-of-turnover intensities for energy, GHG, and water (consolidated revenue basis). These are hardcoded here exactly as printed, each with its own page citation, then converted to per-INR-Crore terms so they are comparable to Part A.
A24: Metric | B24: Wipro's printed value (per Rupee) | C24: Page | D24: Converted to per INR Crore | E24: Formula
A25: Energy (MJ/INR) | B25: 0.00084879 | C25: 506 | D25: =B25*10000000 -> 8487.9 | E25: =B25*10000000 -> 8487.9
A26: GHG (kgCO2e/INR) | B26: 3.5e-05 | C26: 509 | D26: =B26*10000 -> 0.35 | E26: =B26*10000000/1000 -> 0.35
A27: Water (KL/INR) | B27: 1.5e-06 | C27: 507 | D27: =B27*10000000 -> 15 | E27: =B27*10000000 -> 15
A29: Note: Wipro's units differ per metric as printed (GHG in kg, others direct) — column D converts each to a tonnes/MJ/KL-per-crore basis matching Part A. Column E repeats the formula for transparency.
A32: Metric | B32: Our computed (per Crore) | C32: Wipro's printed (per Crore) | D32: Ratio (ours / Wipro's) | E32: Implied revenue base from Wipro's ratio (INR Crore)
A33: GHG | B33: =C16 -> 0.46753887 | C33: =D26 -> 0.35 | D33: =B33/C33 -> 1.3358254 | E33: =C11/D26 -> 89891.429
A34: Water | B34: =C17 -> 19.430474 | C34: =D27 -> 15 | D34: =B34/C34 -> 1.2953649 | E34: =C12/D27 -> 87168.733
A35: Energy | B35: =C18 -> 11237.094 | C35: =D25 -> 8487.9 | D35: =B35/C35 -> 1.3238957 | E35: =C13/D25 -> 89088.647
A37: Reading the reconciliation:
A38: All three ratios cluster near 1.3 (our intensities run about 30% higher than Wipro's own printed figures), and all three independently imply a revenue base of roughly INR 87,000-90,000 Crore rather than the INR 67,293 Crore Section VI turnover used in Part A. Three unrelated metrics converging on the same gap is evidence of one systematic cause (a standalone-vs-consolidated revenue basis difference, consistent with the boundary change Wipro itself discloses at Q13, page 480) rather than three separate errors.

Sheet GRI Coverage
A1: Section 2 - GRI Standards Coverage Mapping (Wipro Sustainability Report FY 2024-25)
A3: Task 2.1 finding:
A4: Wipro publishes a separate 163-page Sustainability Report FY 2024-25 alongside the mandatory BRSR. The report is explicitly GRI-aligned: each substantive section is tagged inline with its GRI disclosure code, and a formal GRI Content Index appears on pages 146-151.
A10: Coverage Summary (5 GRI Standards)
A11: GRI Standard | B11: Title | C11: Total disclosures defined | D11: Addressed by Wipro | E11: Coverage ratio | F11: Coverage Status | G11: Source page(s)
A12: GRI 2 (2021) | B12: General Disclosures | C12: 30 | D12: =COUNTIF(D19:D48,"Yes") -> 30 | E12: =D12/C12 -> 1 | F12: =IF(E12=1,"Strong",IF(E12>=0.5,"Partial",IF(E12>0,"Omitted","Not Disclosed"))) -> Strong | G12: 146-147
A13: GRI 3 (2021) | B13: Material Topics | C13: 3 | D13: =COUNTIF(D51:D53,"Yes") -> 3 | E13: =D13/C13 -> 1 | F13: =IF(E13=1,"Strong",IF(E13>=0.5,"Partial",IF(E13>0,"Omitted","Not Disclosed"))) -> Strong | G13: 147
A14: GRI 305 (2016) | B14: Emissions | C14: 7 | D14: =COUNTIF(D56:D62,"Yes") -> 7 | E14: =D14/C14 -> 1 | F14: =IF(E14=1,"Strong",IF(E14>=0.5,"Partial",IF(E14>0,"Omitted","Not Disclosed"))) -> Strong | G14: 149-150
A15: GRI 303 (2018) | B15: Water and Effluents | C15: 5 | D15: =COUNTIF(D65:D69,"Yes") -> 5 | E15: =D15/C15 -> 1 | F15: =IF(E15=1,"Strong",IF(E15>=0.5,"Partial",IF(E15>0,"Omitted","Not Disclosed"))) -> Strong | G15: 149
A16: GRI 403 (2018) | B16: Occupational Health and Safety | C16: 10 | D16: =COUNTIF(D72:D81,"Yes") -> 10 | E16: =D16/C16 -> 1 | F16: =IF(E16=1,"Strong",IF(E16>=0.5,"Partial",IF(E16>0,"Omitted","Not Disclosed"))) -> Strong | G16: 150-151
A18: GRI 2: General Disclosures 2021 (30 disclosures)
A19: GRI 2-1 | B19: Organizational details | D19: Yes | E19: 10, 146
A20: GRI 2-2 | B20: Entities included in sustainability reporting | D20: Yes | E20: 10, 146
A21: GRI 2-3 | B21: Reporting period, frequency, and contact point | D21: Yes | E21: 10, 146
A22: GRI 2-4 | B22: Restatements of information | D22: Yes | E22: 146
A23: GRI 2-5 | B23: External assurance | D23: Yes | E23: 10, 146
A24: GRI 2-6 | B24: Activities, value chain and other business relationships | D24: Yes | E24: 146
A25: GRI 2-7 | B25: Employees | D25: Yes | E25: 146
A26: GRI 2-8 | B26: Workers who are not employees | D26: Yes | E26: 146
A27: GRI 2-9 | B27: Governance structure and composition | D27: Yes | E27: 15, 146
A28: GRI 2-10 | B28: Nomination and selection of highest governance body | D28: Yes | E28: 16, 146
A29: GRI 2-11 | B29: Chair of the highest governance body | D29: Yes | E29: 16, 146
A30: GRI 2-12 | B30: Role of highest governance body in overseeing management of impacts | D30: Yes | E30: 16, 146
... A48: GRI 2-30 | B48: Collective bargaining agreements | D48: Yes | E48: 147
A50: GRI 3: Material Topics 2021 (3 disclosures)
A51: GRI 3-1 | B51: Process to determine material topics | D51: Yes | E51: 37, 147
A52: GRI 3-2 | B52: List of material topics | D52: Yes | E52: 40, 147
A53: GRI 3-3 | B53: Management of material topics | D53: Yes | E53: 38, 147
A55: GRI 305: Emissions 2016 (7 disclosures)
A56: GRI 305-1 | B56: Direct (Scope 1) GHG emissions | D56: Yes | E56: 68, 149
A57: GRI 305-2 | B57: Energy indirect (Scope 2) GHG emissions | D57: Yes | E57: 68, 149
A58: GRI 305-3 | B58: Other indirect (Scope 3) GHG emissions | D58: Yes | E58: 68, 149
A59: GRI 305-4 | B59: GHG emissions intensity | D59: Yes | E59: 69, 149
A60: GRI 305-5 | B60: Reduction of GHG emissions | D60: Yes | E60: 66, 149
A61: GRI 305-6 | B61: Emissions of ozone-depleting substances (ODS) | D61: Yes | E61: 69, 149
A62: GRI 305-7 | B62: NOx, SOx, and other significant air emissions | D62: Yes | E62: 150
A64: GRI 303: Water and Effluents 2018 (5 disclosures)
A65: GRI 303-1 | B65: Interactions with water as a shared resource | D65: Yes | E65: 74, 149
A66: GRI 303-2 | B66: Management of water discharge-related impacts | D66: Yes | E66: 76, 149
A67: GRI 303-3 | B67: Water withdrawal | D67: Yes | E67: 75, 149
...
